<?xml version="1.0" ?>
<robot name="gripper">
  <!--Generated by CROSS, a ROS Workbench for FreeCAD (https://github.com/galou/freecad.cross)-->
  <link name="Link">
    <visual>
      <!--base_link_part/Body.-->
      <origin rpy="0.0 -0.0 0.0" xyz="0.0 0.0 0.0"/>
      <geometry>
        <mesh filename="package://my_robot_arm/meshes/Unnamed_base_link_body.dae"/>
      </geometry>
    </visual>
    <collision>
      <!--base_link_part/Body.-->
      <origin rpy="0.0 -0.0 0.0" xyz="0.0 0.0 0.0"/>
      <geometry>
        <mesh filename="package://my_robot_arm/meshes/Unnamed_base_link_body.dae"/>
      </geometry>
    </collision>
    <inertial>
      <mass value="0.0"/>
      <origin rpy="0.0 -0.0 0.0" xyz="0.0 0.0 0.0"/>
      <inertia ixx="0.0" ixy="0.0" ixz="0.0" iyy="0.0" iyz="0.0" izz="0.0"/>
    </inertial>
  </link>
  <link name="Link001">
    <visual>
      <!--finger_link_part/Body001.-->
      <origin rpy="0.0 -0.0 0.0" xyz="0.0 0.0 0.0"/>
      <geometry>
        <mesh filename="package://my_robot_arm/meshes/Unnamed_finger_link_body.dae"/>
      </geometry>
    </visual>
    <collision>
      <!--finger_link_part/Body001.-->
      <origin rpy="0.0 -0.0 0.0" xyz="0.0 0.0 0.0"/>
      <geometry>
        <mesh filename="package://my_robot_arm/meshes/Unnamed_finger_link_body.dae"/>
      </geometry>
    </collision>
    <inertial>
      <mass value="0.0"/>
      <origin rpy="0.0 -0.0 0.0" xyz="0.0 0.0 0.0"/>
      <inertia ixx="0.0" ixy="0.0" ixz="0.0" iyy="0.0" iyz="0.0" izz="0.0"/>
    </inertial>
  </link>
  <joint name="Joint" type="prismatic">
    <parent link="Link"/>
    <child link="Link001"/>
    <origin rpy="0.0 -0.0 0.0" xyz="-0.042 0.0 0.06"/>
    <axis xyz="1 0 0"/>
    <limit effort="1000.0" lower="0.0" upper="0.05" velocity="1"/>
  </joint>
</robot>
